Workbook

Sheet Cover Page
C13: Group Assignment
C14: ACT370 (Taxation); Section: 2
C16: Submitted to:
C17: Mr. Rezwanul Mumtahin Husain
C18: Full-Time Faculty, Lecturer
C19: Department of Accounting & Finance
C20: North South University
C22: Submitted By
B23: Name | E23: ID | F23: Serial
B24: Masrul Fahid Islam Rahi | E24: 2131633030 | F24: 13
B25: Faiaz Ahmed Nafiz | E25: 2212391630 | F25: 18
B26: Md. Siddiqur Rahman | E26: 2212821030 | F26: 19
C28: Date of Submission: December 26, 2025

Sheet Return
L1: National Board of Revenue
L2: www.nbr.gov.bd | X2: IT-11GA 2023
A3: For office use
A4: Serial no. in return register | L4: Return of Income
A5: Column no. in return register | L5: For Individual & Other Assessee (without Company)
A6: Date of return submission
A8: 1 | B8: Name of the Assessee: | H8: Samiul Bashar
A10: 2 | B10: National Identification Number/Passport Number (If no NID):
A12: 3 | B12: TIN: | F12: 1 | G12: 2 | H12: 3 | I12: - | J12: 4 | K12: 5 | L12: 6 | M12: - | N12: 7 | O12: 8 | P12: 9 | Q12: 0
A14: 4 | B14: (a) Circle: | M14: (b) Tax Zone:
A16: 5 | B16: Asssessment Year: | H16: 2025-2026 | M16: 6 | N16: Resident Status: | R16: Resident | V16: ✔️ | W16: Non-resident
A18: 7 | B18: Tax payer Status (tick one) : | I18: Individual | L18: ✔️ | M18: Firm | Q18: Hindu Undivided Family | Y18: Other
A20: 8 | B20: Tick on the box below for getting special benefit:
B22: A gazetted war-wounded freedom fighter | N22: Female | R22: Third Gender | W22: Disabled person
B24: Aged 65 years or more | N24: A parent or legal guardian of a person with disability
A26: 9 | B26: Date of birth (DDMMYYYY) | N26: 10 | O26: Name of Spouse:
O28: TIN if spouse is an Assessee:
A30: 11 | B30: Address: | E30: Dhanmondi
B34: Telephone: | N34: Mobile:
B36: e-mail:
A38: 12 | B38: If employed, employer’s name (Latest employer's name in case of multiple employment):
A41: 13 | B41: (a) Name of Organizaion: | I41: Uncharted Ltd.
B43: (b) Business Identification Number (BIN):
A45: 14 | B45: Name & TIN of Partners/Members in case of Frim/Association of person (If needed, please use separate sheet):
A51: Particulars of Income and Tax during the income year ended on | R51: 45473
A53: Name of the Assessee: | G53: =H8 -> Samiul Bashar
O54: TIN: | Q54: =F12 -> 1 | R54: =G12 -> 2 | S54: =H12 -> 3 | T54: =I12 -> - | U54: =J12 -> 4 | V54: =K12 -> 5 | W54: =L12 -> 6 | X54: =M12 -> - | ... AB54: =Q12 -> 0
A56: Particulars of Total Income | Y56: Amount ৳
A58: 1 | B58: Income from Salaries (annex Schedule 1) | X58: ='Sch1'!T46 -> 675466.67
A59: =A58+1 -> 2 | B59: Income from Rent (annex Schedule 2) | X59: ='Sch2-3'!V23 -> 3637000
A60: =A59+1 -> 3 | B60: Agricultural income (annex Schedule 3) | X60: ='Sch2-3'!U39 -> 226000
A61: =A60+1 -> 4 | B61: Income from business (annex Schedule 4) | X61: ='Sch4-5'!T16 -> 454000
A62: =A61+1 -> 5 | B62: Capital gains | X62: 0
A63: =A62+1 -> 6 | B63: Income from Financial Assets (Bank interest/profit, Dividend, Securities etc.) | X63: ='Income from Financial Assets'!C14 -> 85500
A64: =A63+1 -> 7 | B64: Income from other sources (Royalty, License fee, Honorarium, Fees, Govt. Incentive etc.) | X64: ='Income from Other Sources'!C5 -> 155000
A65: =A64+1 -> 8 | B65: Share of income from firm or AOP | X65: ='Income from Firm'!C4 -> 150000
A66: =A65+1 -> 9 | B66: Income of minor or spouse under section (if not assessee) | X66: 0
A67: =A66+1 -> 10 | B67: Foreign income | X67: 0
A68: =A67+1 -> 11 | B68: Total income (aggregate of 1 to 10) | X68: =SUM(X58:AB67) -> 5382966.7
A70: Tax Computation | Y70: Amount ৳
...

Sheet Tax and Rebate Calculation
C1: Tax Calculation
A2: Workings: Net Taxable Income | B2: Amount | C2: Amount
A3: Total Taxable Income | C3: =Return!X68 -> 5382966.7
A4: Less:Reduced Tax Rate Income/Final Tax Liability | F4: Workings: Allowable Investments | H4: Amount
A5: Interest on 3-monthly Shanchaypatra | B5: ='Income from Financial Assets'!B6 -> 30000 | F5: Contribution to DPS (Max allowed Tk. 120,000) | H5: 120000
A6: Interest on 5year's Bangladesh Shanchaypatra | B6: ='Income from Financial Assets'!B7 -> 30000 | C6: =SUM(B5:B6) -> 60000 | F6: Purchase of Primary Share | H6: 50000
A7: Net Taxable Income | C7: =C3-C6 -> 5322966.7 | F7: Purchase of Secondary Share | H7: 100000
F8: Purchase of Debenture | H8: 400000
F9: Employer and Employee's contribution to RPF | H9: ='Workings Income from Employment'!C8*2 -> 96000
F10: Purchase of 5 year's Shanchaypatra | H10: 100000
F11: Donation to President's relief fund | H11: 60000
F12: Total Allowable Investments | H12: =SUM(H5:H11) -> 926000
A13: Workings: Gross Tax Liability | B13: Income | C13: Tax Rate | D13: Tax
A14: On first Tk. 350,000 | B14: 350000 | C14: 0 | D14: =B14*C14 -> 0
A15: Next Tk. 100,000 | B15: 100000 | C15: 0.05 | D15: =B15*C15 -> 5000 | F15: Workings: Taxes Deducted at Source | H15: Amount
A16: Next Tk. 400,000 | B16: 400000 | C16: 0.1 | D16: =B16*C16 -> 40000 | F16: Dividend Paid | H16: ='Income from Financial Assets'!B3*10% -> 500
A17: Next Tk. 500,000 | B17: 500000 | C17: 0.15 | D17: =B17*C17 -> 75000 | F17: Interest on Fixed Deposit | H17: ='Income from Financial Assets'!B4*10% -> 300
A18: Next Tk. 500,000 | B18: 500000 | C18: 0.2 | D18: =B18*C18 -> 100000 | F18: Interest on Post Office Savings Bank | H18: ='Income from Financial Assets'!B5*10% -> 200
A19: Next Tk. 2,000,000 | B19: 2000000 | C19: 0.25 | D19: =B19*C19 -> 500000 | F19: Interest on Debenture | H19: ='Income from Financial Assets'!B8*10% -> 6000
A20: Rest Amount | B20: =C7-SUM(B14:B19) -> 1472966.7 | C20: 0.3 | D20: =B20*C20 -> 441890 | F20: Prize of winning prize bond lottery | H20: ='Income from Other Sources'!C3*20% -> 6000
A21: Net Taxable Income | B21: =SUM(B14:B20) -> 5322966.7 | C21: Total Gross Tax | D21: =SUM(D14:D20) -> 1161890 | F21: Interest on 3-monthly Profit Bearing Shanchaypatra | H21: ='Income from Financial Assets'!B6*10% -> 3000
F22: Interest on 5 years Bangladesh Shanchaypatra | H22: ='Income from Financial Assets'!B7*10% -> 3000
F23: Total TDS | H23: =SUM(H16:H22) -> 19000
A24: Tax Rebate Calculation | C24: Amount
A25: (A) 3% of Net Taxable Income | C25: =B21*3% -> 159689 | D25: Lower of A,B and C
A26: (B) 15% of Allowable Investments | C26: =H12*15% -> 138900
A27: (C) Tk. 1,000,000 | C27: 1000000
A28: Tax Rebate | C28: =MIN(C25:C27) -> 138900
A30: Minimum Tax Comparison | C30: Amount
A31: (A) Assessee living in Dhaka Citicorporation | C31: 5000 | D31: Higher of A and B
A32: (B)Minimum Taxes Deducted at Source | C32: =SUM(H16:H20) -> 13000
A33: Minimum Tax | C33: =MAX(C31:C32) -> 13000
A35: Tax Liability Calculation | C35: Amount
A36: Gross Tax Liability before Tax Rebate | C36: =D21 -> 1161890
A37: (-)Tax Rebate | C37: =C28 -> 138900
A38: Net Tax after Tax Rebate | C38: =C36-C37 -> 1022990
A39: Minimum Tax | C39: =C33 -> 13000
A40: Higher of Net Tax after Tax Rebate and Minimum Tax | C40: =MAXA(C38:C39) -> 1022990
A41: Surcharges
A42: Wealth Surcharge | C42: =0 -> 0
...

Sheet Sch1
A1: Schedule 1
A2: Particulars of income from Salaries
A3: a. This part is applicable for employees receiving Salary under Govt. pay scale
A5: Name of the Assessee:
I6: TIN:
A8: Sl. | B8: Particulars | L8: Income ৳ | P8: Tax exempted Income ৳ (B) | T8: Taxable Income ৳
A9: 1 | B9: Basic pay
A10: =A9+1 -> 2 | B10: Arrear pay (if not included in taxable income earlier)
A11: =A10+1 -> 3 | B11: Special allowance
A12: =A11+1 -> 4 | B12: House rent allowance
A13: =A12+1 -> 5 | B13: Medical allowance
A14: =A13+1 -> 6 | B14: Conveyance allowance
A15: =A14+1 -> 7 | B15: Festival Allowance
A16: =A15+1 -> 8 | B16: Allowance for support staff
A17: =A16+1 -> 9 | B17: Leave allowance
A18: =A17+1 -> 10 | B18: Honorarium/ Reward/Fee
A19: =A18+1 -> 11 | B19: Overtime allowance
A20: =A19+1 -> 12 | B20: Baishakhi Allowance
A21: =A20+1 -> 13 | B21: Interest accrued on provident fund
... A25: =A24+1 -> 17 | B25: Total
A27: b. This part is applicable for employees other than employees receiving Salary under Govt. pay scale
A28: Name of the Assessee: | G28: =Return!G53 -> Samiul Bashar
I29: TIN: | K29: 1 | L29: 2 | M29: 3 | N29: - | O29: 4 | P29: 5 | Q29: 6 | R29: - | S29: 7 | T29: 8 | U29: 9 | V29: 0
A31: Sl. | B31: Particulars | P31: Income ৳ | T31: Income ৳
A32: 1 | B32: Basic pay | P32: ='Workings Income from Employment'!C2 -> 480000
A33: =A32+1 -> 2 | B33: Allowances | P33: ='Workings Income from Employment'!C4 -> 80000
A34: =A33+1 -> 3 | B34: Advance / Arrear Salary | P34: 0
A35: =A34+1 -> 4 | B35: Gratuity, Annuity, Pension or similar benefits | P35: ='Workings Income from Employment'!B10 -> 25000000
A36: =A35+1 -> 5 | B36: Perquisites | P36: ='Workings Income from Employment'!B19 -> 294000
A37: =A36+1 -> 6 | B37: Receipt in lieu of or in addition to salary or wages | P37: ='Workings Income from Employment'!C6 -> 5000
A38: =A37+1 -> 7 | B38: Income from Employees' share scheme | P38: 0
A39: =A38+1 -> 8 | B39: Accomodation benefits | P39: 0
A40: =A39+1 -> 9 | B40: Car benefits | P40: ='Workings Income from Employment'!C5 -> 180000
A41: =A40+1 -> 10 | B41: Any other benefits provided by employer | P41: 0
A42: =A41+1 -> 11 | B42: Employer's contribution to recognized provident fund | P42: ='Workings Income from Employment'!C8 -> 48000
A43: =A42+1 -> 12 | B43: Others | P43: ='Workings Income from Employment'!B32 -> 6600
A44: =A43+1 -> 13 | B44: Total salary income (aggregate of 1 to 12) | T44: =SUM(P32:S43) -> 26093600
A45: =A44+1 -> 14 | B45: Exempted Salary (As per 6th schedule Part 1) | T45: ='Workings Income from Employment'!B27 -> 25418133
A46: =A45+1 -> 15 | B46: Total Income from Salary (13-14) | T46: =T44-T45 -> 675466.67

Sheet Workings Income from Employment
A1: Workings: Income from Salary | B1: Amount | C1: Amount
A2: Basic Salary | C2: =40000*12 -> 480000
A3: Perquisites | C3: =B19 -> 294000
A4: Festival Bonuses | C4: =40000*2 -> 80000
A5: Car Benefits | C5: =15000*12 -> 180000
A6: Compensation from previous employer | C6: 5000
A7: Interest on RPF | C7: 3600
A8: Employer's Contribution to RPF | C8: =C2*10% -> 48000
A9: Commission | C9: 3000
A10: Gratuity (Exempted upto 2.5 crore) | B10: 25000000
A11: -Exempted | B11: =B10 -> 25000000 | C11: =B10-B11 -> 0
A12: Total Receipts from Salary | C12: =SUM(C2:C9) -> 1093600
A14: Workings: Perquisites | B14: Amount
A15: Dearness Allowance | B15: =480000*0.1 -> 48000
A16: House rent allowance | B16: =480000*0.4 -> 192000
A17: Medical allowance | B17: =4000*12 -> 48000
A18: Entertainment allowance | B18: =500*12 -> 6000
A19: Total Perquisites | B19: =SUM(B15:B18) -> 294000
A21: Workings: Exempted Salary | B21: Amount
A22: 1/3 of Total receipts | B22: =C12/3 -> 364533.33
A23: Lower of 1/3rd of total reciepts or tk500,000 | B23: =B22 -> 364533.33
A24: Gratuity | B24: ='Sch1'!P35 -> 25000000
A25: Interest from RPF | B25: =3600 -> 3600
A26: Medical Allowance for kidney surgery | B26: 50000
A27: Exempted salary | B27: =SUM(B23:B26) -> 25418133
A29: Workings: Others | B29: Amount
A30: Commission | B30: 3000
A31: Interest on RPF | B31: 3600
A32: Total | B32: =SUM(B30:B31) -> 6600

Sheet Sch2-3
A1: Schedule 2
A2: (Annex this Schedule to the return of income if you have income from house property)
A4: Name of the Assessee: | G4: =Return!H8 -> Samiul Bashar
I5: TIN: | K5: =Return!D114 -> 1 | L5: =Return!E114 -> 2 | M5: =Return!F114 -> 3 | N5: =Return!G114 -> - | O5: =Return!H114 -> 4 | P5: =Return!I114 -> 5 | Q5: =Return!J114 -> 6 | R5: =Return!K114 -> - | ... V5: =Return!O114 -> 0
A7: Location and Description of property | F7: Total Rent Income Computation | R7: Amount ৳ | V7: Amount ৳
F9: 1 | G9: Rent receipt or Annual Value (whichever is higher) | R9: ='Workings Income from Rent'!B4 -> 5000000 | V9: -
F10: =F9+1 -> 2 | G10: Advance rent receipts
F11: =F10+1 -> 3 | G11: Value of any benefits (in addition to 1 & 2)
F12: =F11+1 -> 4 | G12: Adjusted advance rent
F13: =F12+1 -> 5 | G13: Vacancy Allowance | R13: ='Workings Income from Rent'!B8 -> 80000
F14: =F13+1 -> 6 | G14: Total Rent Income (1+2+3)-4-5 | V14: =R9+R10+R11-R12-R13 -> 4920000
F15: =F14+1 -> 7 | G15: Allowable Deductions | V15: =SUM(R16:U21) -> 1283000
G16: (a) | H16: Repair, Collection, etc. | R16: =V14*0.25 -> 1230000
G17: (b) | H17: Municipal or Local Tax | R17: =12*2000 -> 24000
G18: (c) | H18: Land Revenue
G19: (d) | H19: Interest on Loan/Mortgage/Capital Charge | R19: 5000
G20: (e) | H20: Insurance Premium | R20: =5000*4 -> 20000
G21: (f) | H21: Other, if any | R21: ='Workings Income from Rent'!B11 -> 4000
F22: =F15+1 -> 8 | G22: Total Admissible deductions | V22: =SUM(R16:U21) -> 1283000
F23: =F22+1 -> 9 | G23: Income from house property (06-08) | V23: =V14-V22 -> 3637000
F24: =F23+1 -> 10 | G24: Incase of partial ownership, the share of income
A26: Schedule 3
A27: (This part is applicable for Agricultural income)
A29: Name of the Assessee: | G29: =G4 -> Samiul Bashar
I30: TIN: | K30: =K5 -> 1 | L30: =L5 -> 2 | M30: =M5 -> 3 | N30: =N5 -> - | O30: =O5 -> 4 | P30: =P5 -> 5 | Q30: =Q5 -> 6 | R30: =R5 -> - | ... V30: =V5 -> 0
A32: Nature of Agriculture:
B34: Summary of Income | U34: Amount ৳
A35: 1 | B35: Sale/Turnover/Receipts | U35: ='Workings Income from Agricultur'!D8 -> 400000
A36: 2 | B36: Gross Profit | U36: ='Workings Income from Agricultur'!D8-'Workings Income from Agricultur'!D15 -> 255000
A37: 3 | B37: General Expenses, Selling Expenses, Land Revenue, Rates, Interest of Loan, Insurance Premium and Other expenses | U37: ='Workings Income from Agricultur'!D21 -> 29000
A39: 4 | B39: Net profit (2 minus 3) | U39: =U36-U37 -> 226000

Sheet Workings Income from Rent
A1: Workings: Annual Rent Calculation | B1: Amount
A2: Actual Rent | B2: =40000*12*2*5 -> 4800000
A3: Municipal Value | B3: 5000000
A4: Higher of Actual Rental Value and Municipal Value | B4: =MAX(B2:B3) -> 5000000
A6: Workings: Vacancy | B6: Amount
A7: Per Month Rent | B7: 40000
A8: Vacancy Allowance | B8: =B7*2 -> 80000
A10: Others | B10: Amount
A11: Ground Rent | B11: 4000

Sheet Workings Income from Agricultur
A1: Income From Agriculture | C1: Amount | D1: Amount
A2: Sale of Rice | C2: =100*500 -> 50000
A3: Sale of Jute | C3: =200*700 -> 140000
A4: Sale of Rabi Crops | C4: 80000
A5: Sale of Tea | C5: =100000*60% -> 60000
A6: Income from Borga | C6: 30000
A7: Lease on Agricultural Land | C7: 40000
A8: Total Receipts | D8: =SUM(C2:C7) -> 400000
A10: Admissable Expenses | C10: Amount | D10: Amount
A11: Cost of seeds and fertilizers | C11: 50000
A12: Cultivation Cost | C12: 50000
A13: Transportation Cost | C13: 20000
A14: Processing Cost | C14: 25000
A15: Total Production Cost | D15: =SUM(C11:C14) -> 145000
A16: Land Revenue Paid | C16: 10000
A17: Union Parisad Tax | C17: 5000
A18: Crop Insurance Premium | C18: 6000
A19: Allowable Depreciation | C19: 5000
A20: Interest on Borrowed Fund | C20: 3000
A21: General Expenses | D21: =SUM(C16:C20) -> 29000
A22: Total Admissable Expenses | D22: =D15+D21 -> 174000
A23: Total Income from Agriculture | D23: =D8-D22 -> 226000

Sheet Sch4-5
A1: Schedule 4
A2: (To be annexed to return by an assessee having income from business or profession)
A4: Name of the Assessee: | G4: =Return!H8 -> Samiul Bashar
J5: TIN: | L5: =Return!D114 -> 1 | M5: =Return!E114 -> 2 | N5: =Return!F114 -> 3 | O5: =Return!G114 -> - | P5: =Return!H114 -> 4 | Q5: =Return!I114 -> 5 | R5: =Return!J114 -> 6 | S5: =Return!K114 -> - | ... W5: =Return!O114 -> 0
A7: Name of Business/Profession:
J8: Nature of Business/Profession:
A9: Address:
B11: Summary of Income | T11: Amount ৳
A12: 1 | B12: Sale/Turnover/Receipts | T12: ='Workings Income from Business'!C5 -> 3040000
A13: =A12+1 -> 2 | B13: Gross Profit | T13: ='Workings Income from Business'!C7 -> 640000
A14: =A13+1 -> 3 | B14: General, Administrative, Selling and Other expenses | T14: ='Workings Income from Business'!C12 -> 186000
A15: =A14+1 -> 4 | B15: Bad debt expense
A16: =A15+1 -> 5 | B16: Net profit (2-3-4) | T16: =T13-T14-T15 -> 454000
B18: Summary of Balance Sheet | T18: Amount ৳
A19: =A16+1 -> 6 | B19: Cash and Bank balance
A20: =A19+1 -> 7 | B20: Inventory
A21: =A20+1 -> 8 | B21: Fixed Assets | T21: ='Workings Income from Business'!C16 -> 60000
A22: =A21+1 -> 9 | B22: Other Assets
A23: =A22+1 -> 10 | B23: Total Assets | T23: =SUM(T19:X22) -> 60000
A24: =A23+1 -> 11 | B24: Opening Capital
A25: =A24+1 -> 12 | B25: Net profit
A26: =A25+1 -> 13 | B26: Drawing during the income year
A27: =A26+1 -> 14 | B27: Closing Capital (11+12-13) | T27: =SUM(T24:X25)-T26 -> 0
A28: =A27+1 -> 15 | B28: Liabilities
A29: =A28+1 -> 16 | B29: Total Capital & Liabilities | T29: =T27+T28 -> 0
A31: Schedule 5
A32: To be annexed to return by an assessee claiming investment tax credit (attach proof)
A34: Name of the Assessee: | G34: =G4 -> Samiul Bashar
H35: TIN: | J35: =L5 -> 1 | K35: =M5 -> 2 | L35: =N5 -> 3 | M35: =O5 -> - | N35: =P5 -> 4 | O35: =Q5 -> 5 | P35: =R5 -> 6 | Q35: =S5 -> - | ... U35: =W5 -> 0
A37: Particulars of rebatable investment, contribution, etc.
B39: Particulars of Income | T39: Amount ৳
A40: 1 | B40: Life insurance premium or Contractual "Deferred Annuity" paid in Bangladesh
A41: =A40+1 -> 2 | B41: Contribution to deposit pension/Monthly Saving scheme (not exceeding allowable limit) | T41: ='Tax and Rebate Calculation'!H5 -> 120000
A42: =A41+1 -> 3 | B42: Investment in Govt. securities, Unit certificate, Mutual fund, ETF or Joint investment scheme Unit certificate | T42: ='Tax and Rebate Calculation'!H10 -> 100000
A43: =A42+1 -> 4 | B43: Investment in securities listed with approved Stock Exchange | T43: ='Tax and Rebate Calculation'!H6+'Tax and Rebate Calculation'!H7+'Tax and Rebate Calculation'!H8 -> 550000
A44: =A43+1 -> 5 | B44: Contribution to provident fund to which Provident Fund Act, 1925 applies
A45: =A44+1 -> 6 | B45: Self contribution and employer’s contribution to Recognized Provident Fund | T45: ='Tax and Rebate Calculation'!H9 -> 96000
A46: =A45+1 -> 7 | B46: Contribution to approved Pension Fund
A47: =A46+1 -> 8 | B47: Contribution to Benevolent Fund and Group Insurance Premium
A48: =A47+1 -> 9 | B48: Contribution to Zakat Fund
...

Sheet Workings Income from Business
A2: Workings: Income from Business | B2: Amount | C2: Amount
A3: Sales Receipts | B3: 3000000
A4: Sale of Tea | B4: =100000*40% -> 40000
A5: Total Receipts | C5: =SUM(B3:B4) -> 3040000
A6: Cost of Goods Sold | C6: 2400000
A7: Gross Profit | C7: =C5-C6 -> 640000
A8: Expenses
A9: Salary | B9: 80000
A10: Utility bill, Store Rent & Transportation Cost | B10: 100000
A11: Depreciation on Furniture @10% on WDV | B11: =60000*10% -> 6000
A12: Total Expenses | C12: =SUM(B9:B11) -> 186000
A13: Net Profit | C13: =C7-C12 -> 454000
A15: Fixed Asset | C15: Amount
A16: Furniture | C16: 60000

Sheet Income from Financial Assets
A2: Workings | B2: Amount | C2: Amount
A3: Dividend Received | B3: =4500/0.9 -> 5000
A4: Interest on Fixed Deposit | B4: =2700/0.9 -> 3000
A5: Interest on Post Office Savings Bank | B5: =1800/0.9 -> 2000
A6: Interest on 3-monthly Profit Bearing Shanchaypatra | B6: 30000
A7: Interest on 5 year's Bangladesh Shanchaypatra | B7: =27000/0.9 -> 30000
A8: Interest on Debenture | B8: =400000*15% -> 60000
A9: Total Receipts | C9: =SUM(B3:B8) -> 130000
A10: Allowable Deductions
A11: Interest on loan taken for debenture | B11: =400000*10% -> 40000
A12: Bank Charge | B12: =(COUNT(B6:B8)*1500) -> 4500
A13: Total Allowable Deductions | C13: =SUM(B11:B12) -> 44500
A14: Total Income from Financial Assets | C14: =C9-C13 -> 85500

Sheet Income from Firm
A1: Workings | C1: Amount
A2: Profit From Partnership Firm | C2: 300000
A3: Ownership 1/2
A4: Total Income from Firm | C4: =C2/2 -> 150000

Sheet Income from Other Sources
A2: Workings | C2: Amount
A3: Prize of winning prize bond lottery | C3: =24000/0.8 -> 30000
A4: Unexplained purchase of jewelry | C4: 125000
A5: Total Income from Other Sources | C5: =SUM(C3:C4) -> 155000

Sheet IT-10BB23
W2: IT-10 BB (2023)
A3: Statement of expenses relating to Lifestyle
A4: (applicable for all Individual Assessee)
A6: Name of the Assessee: | G6: =Return!H8 -> Samiul Bashar
J7: TIN: | L7: =Return!D114 -> 1 | M7: =Return!E114 -> 2 | N7: =Return!F114 -> 3 | O7: =Return!G114 -> - | P7: =Return!H114 -> 4 | Q7: =Return!I114 -> 5 | R7: =Return!J114 -> 6 | S7: =Return!K114 -> - | ... W7: =Return!O114 -> 0
A10: Sl. | B10: Particulars of Expenses (Annual) | Q10: Amount ৳ | U10: Comments
A11: 1 | B11: Expenses for food, clothing and other essentials | Q11: ='Workings Lifestyle Expense'!C4 -> 80000
A12: =A11+1 -> 2 | B12: Housing expense | Q12: ='Workings Lifestyle Expense'!C8 -> 2500
A13: =A12+1 -> 3 | B13: Personal Transport Expenses | Q13: ='Workings Lifestyle Expense'!C9 -> 6000
A14: =A13+1 -> 4 | B14: Utility expenses (Electric bill, Gas, Water, Telephone, Mobile, Internet etc.) | Q14: ='Workings Lifestyle Expense'!C7 -> 5000
A15: =A14+1 -> 5 | B15: Education Expenses
A16: =A15+1 -> 6 | B16: Personal Expenses for local & foreign travel, vacation etc. | Q16: ='Workings Lifestyle Expense'!C12 -> 30000
A17: =A16+1 -> 7 | B17: Festival and Other special expenses | Q17: ='Workings Lifestyle Expense'!C11 -> 15000
A18: =A17+1 -> 8 | B18: Tax deducted/collected at source (with tax deducted from profit of saving certificate) and tax & surcharge paid based on last year tax return) | Q18: =Return!S88+Return!S89 -> 19000
A19: =A18+1 -> 9 | B19: Interest paid on personal loan received from Institution & other source | Q19: =400000*10% -> 40000
A20: Total | Q20: =SUM(Q11:T19) -> 197500
A25: Verification
B27: I declare that to the best of my knowledge and belief the information given in this IT-10BB (2023) herewith are correct and complete.
Q33: Signature and date

Sheet IT-10B23
A1: National Board of Revenue
A2: www.nbr.gov.bd
V3: IT-10 B (2023)
A4: Statement of Assets, Liabilities and Expenses
J5: as on…. | L5: =Return!R51 -> 45473
A7: To Whom It May Concern
A8: 1 | B8: All Public Servant
A9: 2 | B9: If the amount of total asset in home and abroad exceeds Taka 40,00,000.
A10: 3 | B10: The amount of total asset does not exceed Taka 40,00,000 but owns a motor car in any time or has made an investment in a house property or an apartment in the city corporation area or owns assets outside Bangladesh or being a shareholder director of a company.
A13: 4 | B13: Every individual assessee, being a non-resident Bangladeshi and individual assessee, being a non-Bangladeshi, shall submit the statement only in respect of assets located in Bangladesh.
A16: Name of the Assessee: | G16: =Return!H8 -> Samiul Bashar
J17: TIN: | L17: =Return!F12 -> 1 | M17: =Return!G12 -> 2 | N17: =Return!H12 -> 3 | O17: =Return!I12 -> - | P17: =Return!J12 -> 4 | Q17: =Return!K12 -> 5 | R17: =Return!L12 -> 6 | S17: =Return!M12 -> - | ... W17: =Return!Q12 -> 0
A19: 1 | B19: Sources of fund: | Q19: Amount (Tk) | U19: Amount (Tk)
B20: (a) | C20: Total income shown in return (sl. no.11 of state. of total income) | Q20: =Return!X68 -> 5382966.7
B21: (b) | C21: Tax Exempted Income | Q21: =Return!X95 -> 25418133
B22: (b) | C22: Receipt of Gift and others | Q22: 0
J23: Total Sources of fund | U23: =SUM(Q20:T22) -> 30801100
A24: 2 | B24: Net wealth at the last date of the previous income year | U24: 0
A25: 3 | B25: Sum of Source of fund and net wealth at the last date of the previous income year (2+3) | U25: =SUM(T23:W24) -> 30801100
A26: 4 | B26: (a) | C26: Expenses relating to Lifestyle (as per IT-10BB) | Q26: ='IT-10BB23'!Q20 -> 197500
B27: (b) | C27: Gift/Expenses/Loss not mentioned in IT-10BB
J28: Total Expenses and Loss | U28: =SUM(Q26:T27) -> 197500
A29: 5 | B29: Net wealth at the last date of this financial year (3-4) | U29: =U25-U28 -> 30603600
A31: 6 | B31: Personal liabilities outside business
B32: (a) | C32: Institutional liabilities | Q32: 400000
B33: (b) | C33: Non-institutional liabilities | O33: =Return!V107 -> 0
B34: (c) | C34: Other liabilities | O34: =Return!V108 -> 0
I35: Total liabilities outside business | U35: =SUM(O32:R34) -> 400000
A36: 7 | B36: Gross wealth (5+6) | U36: =U29+U35 -> 31003600
A37: 8 | B37: Particular of assets (if needed attach separate sheet)
A38: (a) | B38: Aggregate Business capital and liabilities
B39: Less: Business liabilities
A40: (b) | B40: Director's shareholdings in limited companies | U40: 0
A41: (c) | B41: Business capital of Partnership Firm | U41: 0
A42: (d) | B42: Non-Agricultural Property / land / House Property (Acquisition / Cost Value with Legal Expense / Acquired Price / Building Cost / Investment) | U42: =5000000+2000000 -> 7000000
B43: Location and Description of Non-Agricultural Property (use separate sheet if needed) | J43: (Banani & Dhanmondi Address)
A44: (e) | B44: Agricultural Property (Acquisition / Cost Value with Legal Expense) | U44: 0
B45: Location and Description of Non-Agricultural Property (use separate sheet if needed)
A46: (f) | B46: Financial assets
B47: (i) | C47: Share/Debenture/Bond/Securities/Unit Certificate etc. | Q47: ='Sch4-5'!T43 -> 550000
...

Sheet Workings Lifestyle Expense
A3: Workings | B3: Amount | C3: Amount
A4: Living Expense | C4: 80000
A5: Wasa Bill | B5: 3000
A6: Electricity Bill | B6: 2000
A7: Utility Expense | C7: =SUM(B5:B6) -> 5000
A8: Service Charge for Accomodation | C8: 2500
A9: Transportation Expense | C9: 6000
A10: Medical Expense | C10: 25000
A11: Festival Expense | C11: 15000
A12: Foreign Tour | C12: 30000
A13: Total | C13: =SUM(C4:C12) -> 163500
